[2025-08-03T15:47:51.733+0000] {taskinstance.py:1956} INFO - Dependencies all met for dep_context=non-requeueable deps ti=<TaskInstance: dit_uq_stage2.initialize_rl_environment manual__2025-08-03T00:00:00+00:00 [queued]>
[2025-08-03T15:47:51.738+0000] {taskinstance.py:1956} INFO - Dependencies all met for dep_context=requeueable deps ti=<TaskInstance: dit_uq_stage2.initialize_rl_environment manual__2025-08-03T00:00:00+00:00 [queued]>
[2025-08-03T15:47:51.738+0000] {taskinstance.py:2170} INFO - Starting attempt 3 of 3
[2025-08-03T15:47:51.744+0000] {taskinstance.py:2191} INFO - Executing <Task(DockerOperator): initialize_rl_environment> on 2025-08-03 00:00:00+00:00
[2025-08-03T15:47:51.747+0000] {standard_task_runner.py:60} INFO - Started process 1474 to run task
[2025-08-03T15:47:51.748+0000] {standard_task_runner.py:87} INFO - Running: ['***', 'tasks', 'run', 'dit_uq_stage2', 'initialize_rl_environment', 'manual__2025-08-03T00:00:00+00:00', '--job-id', '29', '--raw', '--subdir', 'DAGS_FOLDER/dit_uq_stage2.py', '--cfg-path', '/tmp/tmpj7rca_iv']
[2025-08-03T15:47:51.749+0000] {standard_task_runner.py:88} INFO - Job 29: Subtask initialize_rl_environment
[2025-08-03T15:47:51.767+0000] {task_command.py:423} INFO - Running <TaskInstance: dit_uq_stage2.initialize_rl_environment manual__2025-08-03T00:00:00+00:00 [running]> on host 526a1360f1e8
[2025-08-03T15:47:51.798+0000] {taskinstance.py:2480} INFO - Exporting env vars: AIRFLOW_CTX_DAG_OWNER='molecule-ai-team' AIRFLOW_CTX_DAG_ID='dit_uq_stage2' AIRFLOW_CTX_TASK_ID='initialize_rl_environment' AIRFLOW_CTX_EXECUTION_DATE='2025-08-03T00:00:00+00:00' AIRFLOW_CTX_TRY_NUMBER='3' AIRFLOW_CTX_DAG_RUN_ID='manual__2025-08-03T00:00:00+00:00'
[2025-08-03T15:47:51.827+0000] {docker.py:359} INFO - Starting docker container from image molecule-ai-base:latest
[2025-08-03T15:47:51.836+0000] {docker.py:367} WARNING - Using remote engine or docker-in-docker and mounting temporary volume from host is not supported. Falling back to `mount_tmp_dir=False` mode. You can set `mount_tmp_dir` parameter to False to disable mounting and remove the warning
[2025-08-03T15:47:52.987+0000] {docker.py:429} INFO - Traceback (most recent call last):
  File "<string>", line 19, in <module>
[2025-08-03T15:47:52.988+0000] {docker.py:429} INFO - File "/app/src/rl/__init__.py", line 3, in <module>
[2025-08-03T15:47:52.988+0000] {docker.py:429} INFO - from .molecular_ppo import MolecularPPO, RLGraphDiT
  File "/app/src/rl/molecular_ppo.py", line 14, in <module>
[2025-08-03T15:47:52.989+0000] {docker.py:429} INFO - import wandb
  File "/usr/local/lib/python3.10/site-packages/wandb/__init__.py", line 27, in <module>
    from wandb import sdk as wandb_sdk
  File "/usr/local/lib/python3.10/site-packages/wandb/sdk/__init__.py", line 25, in <module>
    from .artifacts.artifact import Artifact
  File "/usr/local/lib/python3.10/site-packages/wandb/sdk/artifacts/artifact.py", line 35, in <module>
[2025-08-03T15:47:52.990+0000] {docker.py:429} INFO - from wandb import data_types, env, util
  File "/usr/local/lib/python3.10/site-packages/wandb/data_types.py", line 33, in <module>
[2025-08-03T15:47:52.990+0000] {docker.py:429} INFO - from .sdk.data_types import _dtypes
  File "/usr/local/lib/python3.10/site-packages/wandb/sdk/data_types/_dtypes.py", line 396, in <module>
[2025-08-03T15:47:52.990+0000] {docker.py:429} INFO - NumberType.types.append(np.float_)
  File "/usr/local/lib/python3.10/site-packages/numpy/__init__.py", line 400, in __getattr__
[2025-08-03T15:47:52.991+0000] {docker.py:429} INFO - raise AttributeError(
[2025-08-03T15:47:52.991+0000] {docker.py:429} INFO - AttributeError: `np.float_` was removed in the NumPy 2.0 release. Use `np.float64` instead.
[2025-08-03T15:47:53.249+0000] {taskinstance.py:2698} ERROR - Task failed with exception
Traceback (most recent call last):
  File "/home/airflow/.local/lib/python3.8/site-packages/docker/api/client.py", line 265, in _raise_for_status
    response.raise_for_status()
  File "/home/airflow/.local/lib/python3.8/site-packages/requests/models.py", line 1021, in raise_for_status
    raise HTTPError(http_error_msg, response=self)
requests.exceptions.HTTPError: 400 Client Error: Bad Request for url: http+docker://localhost/v1.51/containers/create

The above exception was the direct cause of the following exception:

Traceback (most recent call last):
  File "/home/airflow/.local/lib/python3.8/site-packages/airflow/providers/docker/operators/docker.py", line 364, in _run_image
    return self._run_image_with_mounts([*self.mounts, tmp_mount], add_tmp_variable=True)
  File "/home/airflow/.local/lib/python3.8/site-packages/airflow/providers/docker/operators/docker.py", line 391, in _run_image_with_mounts
    self.container = self.cli.create_container(
  File "/home/airflow/.local/lib/python3.8/site-packages/docker/api/container.py", line 439, in create_container
    return self.create_container_from_config(config, name, platform)
  File "/home/airflow/.local/lib/python3.8/site-packages/docker/api/container.py", line 456, in create_container_from_config
    return self._result(res, True)
  File "/home/airflow/.local/lib/python3.8/site-packages/docker/api/client.py", line 271, in _result
    self._raise_for_status(response)
  File "/home/airflow/.local/lib/python3.8/site-packages/docker/api/client.py", line 267, in _raise_for_status
    raise create_api_error_from_http_exception(e) from e
  File "/home/airflow/.local/lib/python3.8/site-packages/docker/errors.py", line 39, in create_api_error_from_http_exception
    raise cls(e, response=response, explanation=explanation) from e
docker.errors.APIError: 400 Client Error for http+docker://localhost/v1.51/containers/create: Bad Request ("invalid mount config for type "bind": bind source path does not exist: /host_mnt/private/tmp/airflowtmpv4eqb3m5")

During handling of the above exception, another exception occurred:

Traceback (most recent call last):
  File "/home/airflow/.local/lib/python3.8/site-packages/airflow/models/taskinstance.py", line 428, in _execute_task
    result = execute_callable(context=context, **execute_callable_kwargs)
  File "/home/airflow/.local/lib/python3.8/site-packages/airflow/providers/docker/operators/docker.py", line 502, in execute
    return self._run_image()
  File "/home/airflow/.local/lib/python3.8/site-packages/airflow/providers/docker/operators/docker.py", line 373, in _run_image
    return self._run_image_with_mounts(self.mounts, add_tmp_variable=False)
  File "/home/airflow/.local/lib/python3.8/site-packages/airflow/providers/docker/operators/docker.py", line 437, in _run_image_with_mounts
    raise DockerContainerFailedException(f"Docker container failed: {result!r}", logs=log_lines)
airflow.providers.docker.exceptions.DockerContainerFailedException: Docker container failed: {'StatusCode': 1}
[2025-08-03T15:47:53.251+0000] {taskinstance.py:1138} INFO - Marking task as FAILED. dag_id=dit_uq_stage2, task_id=initialize_rl_environment, execution_date=20250803T000000, start_date=20250803T154751, end_date=20250803T154753
[2025-08-03T15:47:53.258+0000] {standard_task_runner.py:107} ERROR - Failed to execute job 29 for task initialize_rl_environment (Docker container failed: {'StatusCode': 1}; 1474)
[2025-08-03T15:47:53.284+0000] {local_task_job_runner.py:234} INFO - Task exited with return code 1
[2025-08-03T15:47:53.296+0000] {taskinstance.py:3280} INFO - 0 downstream tasks scheduled from follow-on schedule check
